Workbook
Name Slicer_Analysis_Year: #N/A
Name Slicer_Final_Seller_Risk: #N/A
Name Slicer_Primary_Category: #N/A
Name Slicer_Region: #N/A

Sheet Violation_Summary_Seller_Year
A1: Seller_ID | B1: Analysis_Year | C1: Violation_Count | D1: Total_Penalty_Amount | E1: Fraud_Linked_Violation_Count | F1: Resolved_Violation_Count | G1: Unresolved_Violation_Count | H1: Critical_High_Severity_Count | I1: Escalated_Open_Violation_Count | J1: Affected_Order_Total | K1: Seller_Year_Key
A2: 1 | B2: 2021 | C2: 2 | D2: 3866.18 | E2: 1 | F2: 0 | G2: 2 | H2: 2 | I2: 2 | J2: 21 | K2: =A2&"_"&B2 -> 1_2021
A3: 1 | B3: 2022 | C3: 6 | D3: 18392.1 | E3: 6 | F3: 2 | G3: 4 | H3: 5 | I3: 2 | J3: 51 | K3: =A3&"_"&B3 -> 1_2022
A4: 1 | B4: 2023 | C4: 2 | D4: 1097.65 | E4: 0 | F4: 1 | G4: 1 | H4: 0 | I4: 0 | J4: 5 | K4: =A4&"_"&B4 -> 1_2023
A5: 1 | B5: 2024 | C5: 1 | D5: 1362.14 | E5: 0 | F5: 0 | G5: 1 | H5: 0 | I5: 0 | J5: 5 | K5: =A5&"_"&B5 -> 1_2024
A6: 1 | B6: 2025 | C6: 5 | D6: 17489.86 | E6: 4 | F6: 1 | G6: 4 | H6: 4 | I6: 1 | J6: 33 | K6: =A6&"_"&B6 -> 1_2025
A7: 2 | B7: 2021 | C7: 6 | D7: 9238.55 | E7: 5 | F7: 5 | G7: 1 | H7: 3 | I7: 2 | J7: 80 | K7: =A7&"_"&B7 -> 2_2021
A8: 2 | B8: 2022 | C8: 3 | D8: 5559.3 | E8: 0 | F8: 2 | G8: 1 | H8: 2 | I8: 2 | J8: 29 | K8: =A8&"_"&B8 -> 2_2022
A9: 2 | B9: 2023 | C9: 6 | D9: 17782.71 | E9: 5 | F9: 4 | G9: 2 | H9: 5 | I9: 3 | J9: 43 | K9: =A9&"_"&B9 -> 2_2023
A10: 2 | B10: 2024 | C10: 4 | D10: 4292.62 | E10: 0 | F10: 2 | G10: 2 | H10: 2 | I10: 1 | J10: 20 | K10: =A10&"_"&B10 -> 2_2024
A11: 2 | B11: 2025 | C11: 1 | D11: 2596.4 | E11: 0 | F11: 1 | G11: 0 | H11: 1 | I11: 0 | J11: 11 | K11: =A11&"_"&B11 -> 2_2025
A12: 3 | B12: 2021 | C12: 6 | D12: 17324.54 | E12: 4 | F12: 3 | G12: 3 | H12: 6 | I12: 5 | J12: 47 | K12: =A12&"_"&B12 -> 3_2021
A13: 3 | B13: 2022 | C13: 6 | D13: 15055.12 | E13: 3 | F13: 4 | G13: 2 | H13: 3 | I13: 2 | J13: 34 | K13: =A13&"_"&B13 -> 3_2022
... A480: 100 | B480: 2025 | C480: 5 | D480: 8908.72 | E480: 0 | F480: 2 | G480: 3 | H480: 3 | I480: 2 | J480: 27 | K480: =A480&"_"&B480 -> 100_2025

Sheet Cleaned_Violation_Log
A1: Violation_ID | B1: Seller_ID | C1: Violation_Date | D1: Violation_Year | E1: Violation_Type | F1: Severity_Level | G1: Violation_Status | H1: Reported_Source | I1: Affected_Order_Count | J1: Penalty_Amount | K1: Fraud_Linked_Flag | L1: Action_Taken | M1: Resolved_Flag
A2: V00001 | B2: 1 | C2: 44458 | D2: 2021 | E2: Policy Breach | F2: High | G2: Escalated | H2: Compliance Team | I2: 12 | J2: 1343.5 | K2: 1 | L2: Payout Hold | M2: 0
A3: V00002 | B3: 1 | C3: 44422 | D3: 2021 | E3: Policy Breach | F3: High | G3: Escalated | H3: User | I3: 9 | J3: 2522.68 | K3: 0 | L3: Seller Suspended | M3: 0
A4: V00003 | B4: 1 | C4: 44873 | D4: 2022 | E4: Fraud Suspicion | F4: Critical | G4: Open | H4: Compliance Team | I4: 9 | J4: 6847.81 | K4: 1 | L4: Listing Removed | M4: 1
A5: V00004 | B5: 1 | C5: 44723 | D5: 2022 | E5: Fraud Suspicion | F5: High | G5: Under Investigation | H5: System Detection | I5: 7 | J5: 2174.09 | K5: 1 | L5: Payout Hold | M5: 0
A6: V00005 | B6: 1 | C6: 44848 | D6: 2022 | E6: Fraud Suspicion | F6: High | G6: Escalated | H6: Internal Audit | I6: 8 | J6: 3712.51 | K6: 1 | L6: Listing Removed | M6: 0
A7: V00006 | B7: 1 | C7: 44637 | D7: 2022 | E7: Fraud Suspicion | F7: High | G7: Under Investigation | H7: Compliance Team | I7: 4 | J7: 3750 | K7: 1 | L7: Seller Suspended | M7: 0
A8: V00007 | B8: 1 | C8: 44595 | D8: 2022 | E8: Fraud Suspicion | F8: Low | G8: Under Investigation | H8: Compliance Team | I8: 10 | J8: 326.2 | K8: 1 | L8: No Action | M8: 0
A9: V00008 | B9: 1 | C9: 44900 | D9: 2022 | E9: Policy Breach | F9: High | G9: Closed | H9: Compliance Team | I9: 13 | J9: 1581.49 | K9: 1 | L9: Listing Removed | M9: 1
A10: V00009 | B10: 1 | C10: 45068 | D10: 2023 | E10: Late Fulfillment | F10: Low | G10: Under Investigation | H10: Compliance Team | I10: 2 | J10: 590.88 | K10: 0 | L10: Warning Issued | M10: 1
A11: V00010 | B11: 1 | C11: 44961 | D11: 2023 | E11: Late Fulfillment | F11: Low | G11: Under Investigation | H11: Compliance Team | I11: 3 | J11: 506.77 | K11: 0 | L11: Warning Issued | M11: 0
A12: V00011 | B12: 1 | C12: 45476 | D12: 2024 | E12: Late Fulfillment | F12: Medium | G12: Under Investigation | H12: System Detection | I12: 5 | J12: 1362.14 | K12: 0 | L12: Listing Removed | M12: 0
A13: V00012 | B13: 1 | C13: 45663 | D13: 2025 | E13: Product Quality Issue | F13: Critical | G13: Under Investigation | H13: Internal Audit | I13: 1 | J13: 7972.04 | K13: 1 | L13: Payout Hold | M13: 0
... A1647: V01646 | B1647: 100 | C1647: 45967 | D1647: 2025 | E1647: Listing Misrepresentation | F1647: Medium | G1647: Under Investigation | H1647: Internal Audit | I1647: 3 | J1647: 1018.45 | K1647: 0 | L1647: Listing Removed | M1647: 0

Sheet Raw_Violation_Log
A1: Violation_ID | B1: Seller_ID | C1: Violation_Date | D1: Violation_Year | E1: Violation_Type | F1: Severity_Level | G1: Violation_Status | H1: Reported_Source | I1: Affected_Order_Count | J1: Penalty_Amount | K1: Fraud_Linked_Flag | L1: Action_Taken | M1: Resolved_Flag
A2: V00001 | B2: 1 | C2: 44458 | D2: 2021 | E2: Policy Breach | F2: High | G2: Escalated | H2: Compliance Team | I2: 12 | J2: 1343.5 | K2: 1 | L2: Payout Hold | M2: 0
A3: V00002 | B3: 1 | C3: 44422 | D3: 2021 | E3: Policy Breach | F3: High | G3: Escalated | H3: User | I3: 9 | J3: 2522.68 | K3: 0 | L3: Seller Suspended | M3: 0
A4: V00003 | B4: 1 | C4: 44873 | D4: 2022 | E4: Fraud Suspicion | F4: Critical | G4: Open | H4: Compliance Team | I4: 9 | J4: 6847.81 | K4: 1 | L4: Listing Removed | M4: 1
A5: V00004 | B5: 1 | C5: 44723 | D5: 2022 | E5: Fraud Suspicion | F5: High | G5: Under Investigation | H5: System Detection | I5: 7 | J5: 2174.09 | K5: 1 | L5: Payout Hold | M5: 0
A6: V00005 | B6: 1 | C6: 44848 | D6: 2022 | E6: Fraud Suspicion | F6: High | G6: Escalated | H6: Internal Audit | I6: 8 | J6: 3712.51 | K6: 1 | L6: Listing Removed | M6: 0
A7: V00006 | B7: 1 | C7: 44637 | D7: 2022 | E7: Fraud Suspicion | F7: High | G7: Under Investigation | H7: Compliance Team | I7: 4 | J7: 3750 | K7: 1 | L7: Seller Suspended | M7: 0
A8: V00007 | B8: 1 | C8: 44595 | D8: 2022 | E8: Fraud Suspicion | F8: Low | G8: Under Investigation | H8: Compliance Team | I8: 10 | J8: 326.2 | K8: 1 | L8: No Action | M8: 0
A9: V00008 | B9: 1 | C9: 44900 | D9: 2022 | E9: Policy Breach | F9: High | G9: Closed | H9: Compliance Team | I9: 13 | J9: 1581.49 | K9: 1 | L9: Listing Removed | M9: 1
A10: V00009 | B10: 1 | C10: 45068 | D10: 2023 | E10: Late Fulfillment | F10: Low | G10: Under Investigation | H10: Compliance Team | I10: 2 | J10: 590.88 | K10: 0 | L10: Warning Issued | M10: 1
A11: V00010 | B11: 1 | C11: 44961 | D11: 2023 | E11: Late Fulfillment | F11: Low | G11: Under Investigation | H11: Compliance Team | I11: 3 | J11: 506.77 | K11: 0 | L11: Warning Issued | M11: 0
A12: V00011 | B12: 1 | C12: 45476 | D12: 2024 | E12: Late Fulfillment | F12: Medium | G12: Under Investigation | H12: System Detection | I12: 5 | J12: 1362.14 | K12: 0 | L12: Listing Removed | M12: 0
A13: V00012 | B13: 1 | C13: 45663 | D13: 2025 | E13: Product Quality Issue | F13: Critical | G13: Under Investigation | H13: Internal Audit | I13: 1 | J13: 7972.04 | K13: 1 | L13: Payout Hold | M13: 0
... A1647: V01646 | B1647: 100 | C1647: 45967 | D1647: 2025 | E1647: Listing Misrepresentation | F1647: Medium | G1647: Under Investigation | H1647: Internal Audit | I1647: 3 | J1647: 1018.45 | K1647: 0 | L1647: Listing Removed | M1647: 0

Sheet Cleaned_Governance_Metrics
A1: Seller_ID | B1: Metric_Year | C1: Total_Orders | D1: Returned_Orders | E1: Refund_Requests | F1: Refund_Amount | G1: Refund_Rate | H1: User_Reports_Count | I1: Negative_Review_Count | J1: Customer_Dispute_Count | K1: Policy_Violation_Count | L1: Fraud_Flag | M1: Fraud_Review_Count | N1: Escalation_Count | O1: Chargeback_Count | P1: Governance_Action_Status
A2: 1 | B2: 2021 | C2: 1639 | D2: 93 | E2: 72 | F2: 4476.59 | G2: 0.043929 | H2: 12 | I2: 33 | J2: 11 | K2: 7 | L2: 1 | M2: 4 | N2: 4 | O2: 3 | P2: Suspended
A3: 2 | B3: 2021 | C3: 2638 | D3: 254 | E3: 224 | F3: 9826.34 | G3: 0.084913 | H3: 26 | I3: 83 | J3: 21 | K3: 11 | L3: 1 | M3: 4 | N3: 5 | O3: 8 | P3: Suspended
A4: 3 | B4: 2021 | C4: 747 | D4: 70 | E4: 61 | F4: 4657.6 | G4: 0.08166 | H4: 20 | I4: 25 | J4: 14 | K4: 12 | L4: 1 | M4: 7 | N4: 6 | O4: 2 | P4: Suspended
A5: 4 | B5: 2021 | C5: 480 | D5: 41 | E5: 36 | F5: 2011.28 | G5: 0.075 | H5: 19 | I5: 19 | J5: 9 | K5: 8 | L5: 1 | M5: 6 | N5: 6 | O5: 5 | P5: Suspended
A6: 5 | B6: 2021 | C6: 80 | D6: 9 | E6: 7 | F6: 570.73 | G6: 0.0875 | H6: 13 | I6: 13 | J6: 4 | K6: 5 | L6: 1 | M6: 4 | N6: 3 | O6: 2 | P6: Suspended
A7: 6 | B7: 2021 | C7: 881 | D7: 51 | E7: 46 | F7: 1423.51 | G7: 0.052213 | H7: 14 | I7: 24 | J7: 7 | K7: 9 | L7: 0 | M7: 3 | N7: 4 | O7: 3 | P7: Review Required
A8: 7 | B8: 2021 | C8: 792 | D8: 69 | E8: 65 | F8: 6991.26 | G8: 0.082071 | H8: 30 | I8: 30 | J8: 13 | K8: 12 | L8: 1 | M8: 5 | N8: 7 | O8: 3 | P8: Suspended
A9: 8 | B9: 2021 | C9: 575 | D9: 47 | E9: 38 | F9: 2474.85 | G9: 0.066087 | H9: 8 | I9: 16 | J9: 8 | K9: 5 | L9: 1 | M9: 5 | N9: 3 | O9: 4 | P9: Suspended
A10: 9 | B10: 2021 | C10: 892 | D10: 47 | E10: 38 | F10: 3271.85 | G10: 0.042601 | H10: 13 | I10: 24 | J10: 8 | K10: 3 | L10: 1 | M10: 2 | N10: 3 | O10: 3 | P10: Restricted
A11: 10 | B11: 2021 | C11: 1054 | D11: 64 | E11: 49 | F11: 4827.25 | G11: 0.04649 | H11: 19 | I11: 23 | J11: 8 | K11: 9 | L11: 0 | M11: 3 | N11: 3 | O11: 4 | P11: Review Required
A12: 12 | B12: 2021 | C12: 1863 | D12: 169 | E12: 126 | F12: 5399.95 | G12: 0.067633 | H12: 41 | I12: 61 | J12: 13 | K12: 21 | L12: 1 | M12: 6 | N12: 9 | O12: 6 | P12: Suspended
A13: 13 | B13: 2021 | C13: 241 | D13: 24 | E13: 19 | F13: 2150.92 | G13: 0.078838 | H13: 15 | I13: 16 | J13: 7 | K13: 6 | L13: 0 | M13: 1 | N13: 4 | O13: 1 | P13: Suspended
... A480: 100 | B480: 2025 | C480: 1277 | D480: 141 | E480: 116 | F480: 7559.22 | G480: 0.090838 | H480: 36 | I480: 50 | J480: 26 | K480: 21 | L480: 0 | M480: 3 | N480: 9 | O480: 8 | P480: Restricted

Sheet Raw_Governance_Metrics
A1: Seller_ID | B1: Metric_Year | C1: Total_Orders | D1: Returned_Orders | E1: Refund_Requests | F1: Refund_Amount | G1: Refund_Rate | H1: User_Reports_Count | I1: Negative_Review_Count | J1: Customer_Dispute_Count | K1: Policy_Violation_Count | L1: Fraud_Flag | M1: Fraud_Review_Count | N1: Escalation_Count | O1: Chargeback_Count | P1: Governance_Action_Status
A2: 1 | B2: 2021 | C2: 1639 | D2: 93 | E2: 72 | F2: 4476.59 | G2: 0.043929 | H2: 12 | I2: 33 | J2: 11 | K2: 7 | L2: 1 | M2: 4 | N2: 4 | O2: 3 | P2: Suspended
A3: 1 | B3: 2022 | C3: 806 | D3: 70 | E3: 64 | F3: 5048.02 | G3: 0.079404 | H3: 18 | I3: 26 | J3: 10 | K3: 6 | L3: 1 | M3: 6 | N3: 6 | O3: 4 | P3: Suspended
A4: 1 | B4: 2023 | C4: 398 | D4: 20 | E4: 15 | F4: 518.56 | G4: 0.037688 | H4: 10 | I4: 10 | J4: 4 | K4: 4 | L4: 0 | M4: 1 | N4: 2 | O4: 0 | P4: Review Required
A5: 1 | B5: 2024 | C5: 80 | D5: 2 | E5: 2 | F5: 92.54 | G5: 0.025 | H5: 1 | I5: 1 | J5: 1 | K5: 1 | L5: 0 | M5: 0 | N5: 1 | O5: 0 | P5: Watchlist
A6: 1 | B6: 2025 | C6: 791 | D6: 65 | E6: 56 | F6: 2300.1 | G6: 0.070796 | H6: 12 | I6: 21 | J6: 11 | K6: 7 | L6: 1 | M6: 5 | N6: 4 | O6: 2 | P6: Suspended
A7: 2 | B7: 2021 | C7: 2638 | D7: 254 | E7: 224 | F7: 9826.34 | G7: 0.084913 | H7: 26 | I7: 83 | J7: 21 | K7: 11 | L7: 1 | M7: 4 | N7: 5 | O7: 8 | P7: Suspended
A8: 2 | B8: 2022 | C8: 1666 | D8: 160 | E8: 146 | F8: 6387.33 | G8: 0.087635 | H8: 30 | I8: 46 | J8: 14 | K8: 15 | L8: 0 | M8: 4 | N8: 7 | O8: 3 | P8: Restricted
A9: 2 | B9: 2023 | C9: 713 | D9: 68 | E9: 64 | F9: 2858.51 | G9: 0.089762 | H9: 30 | I9: 30 | J9: 13 | K9: 11 | L9: 1 | M9: 6 | N9: 6 | O9: 3 | P9: Suspended
A10: 2 | B10: 2024 | C10: 715 | D10: 67 | E10: 61 | F10: 6166.17 | G10: 0.085315 | H10: 16 | I10: 21 | J10: 9 | K10: 8 | L10: 0 | M10: 2 | N10: 4 | O10: 4 | P10: Restricted
A11: 2 | B11: 2025 | C11: 690 | D11: 35 | E11: 30 | F11: 2785.56 | G11: 0.043478 | H11: 13 | I11: 13 | J11: 4 | K11: 5 | L11: 0 | M11: 1 | N11: 2 | O11: 1 | P11: Review Required
A12: 3 | B12: 2021 | C12: 747 | D12: 70 | E12: 61 | F12: 4657.6 | G12: 0.08166 | H12: 20 | I12: 25 | J12: 14 | K12: 12 | L12: 1 | M12: 7 | N12: 6 | O12: 2 | P12: Suspended
A13: 3 | B13: 2022 | C13: 1199 | D13: 121 | E13: 102 | F13: 5475.16 | G13: 0.085071 | H13: 29 | I13: 39 | J13: 17 | K13: 16 | L13: 1 | M13: 5 | N13: 8 | O13: 8 | P13: Suspended
... A480: 100 | B480: 2025 | C480: 1277 | D480: 141 | E480: 116 | F480: 7559.22 | G480: 0.090838 | H480: 36 | I480: 50 | J480: 26 | K480: 21 | L480: 0 | M480: 3 | N480: 9 | O480: 8 | P480: Restricted

Sheet Cleaned_Seller_Master
A1: Seller_ID | B1: Seller_Name | C1: Seller_Type | D1: Primary_Category | E1: Region | F1: Country | G1: Onboarding_Date | H1: Marketplace_Tier | I1: Business_Size | J1: KYC_Status | K1: Preferred_Fulfillment_Mode | L1: Account_Status
A2: 1 | B2: Swift Goods 001 | C2: Enterprise | D2: Electronics | E2: Southeast Asia | F2: Singapore | G2: 01-01-2023 | H2: Standard | I2: Small | J2: Verified | K2: Self-fulfilled | L2: Active
A3: 2 | B3: Blue Source 002 | C3: Enterprise | D3: Home | E3: South | F3: Indonesia | G3: 25-01-2022 | H3: Verified | I3: Large | J3: Verified | K3: Platform Fulfilled | L3: Under Review
A4: 3 | B4: Vertex Supply 003 | C4: Individual | D4: Electronics | E4: West | F4: Singapore | G4: 20-06-2023 | H4: Standard | I4: Small | J4: Rejected | K4: Self-fulfilled | L4: Under Review
A5: 4 | B5: Zen Mart 004 | C5: SME | D5: Fashion | E5: Southeast Asia | F5: Malaysia | G5: 03-12-2021 | H5: Standard | I5: Small | J5: Rejected | K5: Self-fulfilled | L5: Active
A6: 5 | B6: True House 005 | C6: Individual | D6: Fashion | E6: West | F6: Malaysia | G6: 12-06-2020 | H6: Standard | I6: Small | J6: Verified | K6: Self-fulfilled | L6: Active
A7: 6 | B7: Core Traders 006 | C7: Brand Partner | D7: Beauty | E7: South | F7: Indonesia | G7: 21-05-2023 | H7: Premium | I7: Large | J7: Verified | K7: Self-fulfilled | L7: Active
A8: 7 | B8: Urban Works 007 | C8: SME | D8: Fashion | E8: West | F8: Malaysia | G8: 19-04-2018 | H8: Premium | I8: Large | J8: Verified | K8: Self-fulfilled | L8: Under Review
A9: 8 | B9: Bright Nest 008 | C9: Enterprise | D9: Fashion | E9: South | F9: India | G9: 19-12-2021 | H9: Verified | I9: Medium | J9: Pending | K9: Platform Fulfilled | L9: Active
A10: 9 | B10: Golden Hub 009 | C10: SME | D10: Electronics | E10: North | F10: India | G10: 14-11-2020 | H10: Strategic | I10: Medium | J10: Verified | K10: Platform Fulfilled | L10: Active
A11: 10 | B11: Ever Merchants 010 | C11: SME | D11: Electronics | E11: North | F11: Thailand | G11: 11-11-2022 | H11: Standard | I11: Small | J11: Verified | K11: Platform Fulfilled | L11: Under Review
A12: 11 | B12: Orbit Square 011 | C12: Enterprise | D12: Groceries | E12: South | F12: Thailand | G12: 10-11-2018 | H12: Strategic | I12: Large | J12: Verified | K12: Platform Fulfilled | L12: Active
A13: 12 | B13: Pulse Commerce 012 | C13: Individual | D13: Groceries | E13: North | F13: Thailand | G13: 01-08-2023 | H13: Verified | I13: Small | J13: Verified | K13: Platform Fulfilled | L13: Restricted
... A101: 100 | B101: Nova Cart 100 | C101: Enterprise | D101: Groceries | E101: Southeast Asia | F101: Indonesia | G101: 04-12-2018 | H101: Verified | I101: Large | J101: Verified | K101: Platform Fulfilled | L101: Active

Sheet Raw_Seller_Master
A1: Seller_ID | B1: Seller_Name | C1: Seller_Type | D1: Primary_Category | E1: Region | F1: Country | G1: Onboarding_Date | H1: Marketplace_Tier | I1: Business_Size | J1: KYC_Status | K1: Preferred_Fulfillment_Mode | L1: Account_Status
A2: 1 | B2: Swift Goods 001 | C2: Enterprise | D2: Electronics | E2: Southeast Asia | F2: Singapore | G2: 44927 | H2: Standard | I2: Small | J2: Verified | K2: Self-fulfilled | L2: Active
A3: 2 | B3: Blue Source 002 | C3: Enterprise | D3: Home | E3: South | F3: Indonesia | G3: 44586 | H3: Verified | I3: Large | J3: Verified | K3: Platform Fulfilled | L3: Under Review
A4: 3 | B4: Vertex Supply 003 | C4: Individual | D4: Electronics | E4: West | F4: Singapore | G4: 45097 | H4: Standard | I4: Small | J4: Rejected | K4: Self-fulfilled | L4: Under Review
A5: 4 | B5: Zen Mart 004 | C5: SME | D5: Fashion | E5: Southeast Asia | F5: Malaysia | G5: 44533 | H5: Standard | I5: Small | J5: Rejected | K5: Self-fulfilled | L5: Active
A6: 5 | B6: True House 005 | C6: Individual | D6: Fashion | E6: West | F6: Malaysia | G6: 43994 | H6: Standard | I6: Small | J6: Verified | K6: Self-fulfilled | L6: Active
A7: 6 | B7: Core Traders 006 | C7: Brand Partner | D7: Beauty | E7: South | F7: Indonesia | G7: 45067 | H7: Premium | I7: Large | J7: Verified | K7: Self-fulfilled | L7: Active
A8: 7 | B8: Urban Works 007 | C8: SME | D8: Fashion | E8: West | F8: Malaysia | G8: 43209 | H8: Premium | I8: Large | J8: Verified | K8: Self-fulfilled | L8: Under Review
A9: 8 | B9: Bright Nest 008 | C9: Enterprise | D9: Fashion | E9: South | F9: India | G9: 44549 | H9: Verified | I9: Medium | J9: Pending | K9: Platform Fulfilled | L9: Active
A10: 9 | B10: Golden Hub 009 | C10: SME | D10: Electronics | E10: North | F10: India | G10: 44149 | H10: Strategic | I10: Medium | J10: Verified | K10: Platform Fulfilled | L10: Active
A11: 10 | B11: Ever Merchants 010 | C11: SME | D11: Electronics | E11: North | F11: Thailand | G11: 44876 | H11: Standard | I11: Small | J11: Verified | K11: Platform Fulfilled | L11: Under Review
A12: 11 | B12: Orbit Square 011 | C12: Enterprise | D12: Groceries | E12: South | F12: Thailand | G12: 43414 | H12: Strategic | I12: Large | J12: Verified | K12: Platform Fulfilled | L12: Active
A13: 12 | B13: Pulse Commerce 012 | C13: Individual | D13: Groceries | E13: North | F13: Thailand | G13: 45139 | H13: Verified | I13: Small | J13: Verified | K13: Platform Fulfilled | L13: Restricted
... A101: 100 | B101: Nova Cart 100 | C101: Enterprise | D101: Groceries | E101: Southeast Asia | F101: Indonesia | G101: 43438 | H101: Verified | I101: Large | J101: Verified | K101: Platform Fulfilled | L101: Active

Sheet Cleaned_Supplier_Risk
A1: Seller_ID | B1: Risk_Year | C1: Financial_Stability_Score | D1: Delivery_Performance_Score | E1: Quality_Compliance_Score | F1: Regulatory_Adherence_Score | G1: Sustainability_Score | H1: Past_Risk_Level | I1: ERP_Transactions | J1: Incidents_Count | K1: MCDM_Score | L1: Risk_Category
A2: 1 | B2: 2021 | C2: 0.3 | D2: 0.42 | E2: 0.8 | F2: 0.96 | G2: 0.47 | H2: 0.47 | I2: 490 | J2: 12 | K2: 0.55 | L2: Medium
A3: 1 | B3: 2021 | C3: 0.4 | D3: 0.81 | E3: 0.95 | F3: 0.9 | G3: 0.35 | H3: 0.9 | I3: 257 | J3: 7 | K3: 0.68 | L3: Medium
A4: 1 | B4: 2021 | C4: 0.45 | D4: 0.81 | E4: 0.79 | F4: 0.82 | G4: 0.9 | H4: 0.1 | I4: 105 | J4: 4 | K4: 0.71 | L4: High
A5: 1 | B5: 2021 | C5: 0.5 | D5: 0.65 | E5: 0.76 | F5: 0.65 | G5: 0.32 | H5: 0.15 | I5: 202 | J5: 8 | K5: 0.59 | L5: Medium
A6: 1 | B6: 2021 | C6: 0.77 | D6: 0.67 | E6: 0.84 | F6: 0.63 | G6: 0.9 | H6: 0.78 | I6: 496 | J6: 2 | K6: 0.75 | L6: High
A7: 2 | B7: 2021 | C7: 0.87 | D7: 0.61 | E7: 0.63 | F7: 0.75 | G7: 0.71 | H7: 0.27 | I7: 310 | J7: 4 | K7: 0.72 | L7: High
A8: 2 | B8: 2021 | C8: 0.77 | D8: 0.68 | E8: 0.71 | F8: 0.86 | G8: 0.68 | H8: 0.06 | I8: 473 | J8: 5 | K8: 0.74 | L8: High
A9: 2 | B9: 2021 | C9: 0.79 | D9: 0.77 | E9: 0.93 | F9: 0.69 | G9: 0.91 | H9: 0.79 | I9: 496 | J9: 8 | K9: 0.81 | L9: High
A10: 2 | B10: 2021 | C10: 0.81 | D10: 0.75 | E10: 0.6 | F10: 0.8 | G10: 0.52 | H10: 0.43 | I10: 423 | J10: 19 | K10: 0.72 | L10: High
A11: 2 | B11: 2021 | C11: 0.9 | D11: 0.79 | E11: 0.72 | F11: 0.74 | G11: 0.31 | H11: 0.83 | I11: 390 | J11: 11 | K11: 0.75 | L11: High
A12: 2 | B12: 2021 | C12: 0.64 | D12: 0.93 | E12: 0.78 | F12: 0.87 | G12: 0.54 | H12: 0.57 | I12: 491 | J12: 3 | K12: 0.77 | L12: High
A13: 3 | B13: 2021 | C13: 0.67 | D13: 0.73 | E13: 0.83 | F13: 0.75 | G13: 0.75 | H13: 0.04 | I13: 215 | J13: 10 | K13: 0.74 | L13: High
... A1801: 100 | B1801: 2025 | C1801: 0.97 | D1801: 0.99 | E1801: 0.9 | F1801: 0.68 | G1801: 0.45 | H1801: 0.34 | I1801: 110 | J1801: 13 | K1801: 0.87 | L1801: High

Sheet Raw_Supplier_Risk
A1: Supplier_ID | B1: Year | C1: Financial_Stability_Score | D1: Delivery_Performance_Score | E1: Quality_Compliance_Score | F1: Regulatory_Adherence_Score | G1: Sustainability_Score | H1: Past_Risk_Level | I1: ERP_Transactions | J1: Incidents_Count | K1: MCDM_Score | L1: Risk_Category
A2: 52 | B2: 2025 | C2: 0.43 | D2: 0.87 | E2: 0.8 | F2: 0.78 | G2: 0.37 | H2: 0.46 | I2: 422 | J2: 3 | K2: 0.66 | L2: Medium
A3: 24 | B3: 2023 | C3: 0.31 | D3: 0.98 | E3: 0.92 | F3: 0.68 | G3: 0.43 | H3: 0.18 | I3: 363 | J3: 11 | K3: 0.67 | L3: Medium
A4: 89 | B4: 2021 | C4: 0.67 | D4: 0.64 | E4: 0.52 | F4: 0.99 | G4: 0.46 | H4: 0.09 | I4: 495 | J4: 18 | K4: 0.66 | L4: Medium
A5: 55 | B5: 2024 | C5: 0.71 | D5: 0.43 | E5: 0.8 | F5: 0.67 | G5: 0.35 | H5: 0.95 | I5: 365 | J5: 13 | K5: 0.62 | L5: Medium
A6: 9 | B6: 2022 | C6: 0.37 | D6: 0.81 | E6: 0.72 | F6: 0.65 | G6: 0.65 | H6: 0.03 | I6: 255 | J6: 16 | K6: 0.62 | L6: Medium
A7: 36 | B7: 2022 | C7: 0.76 | D7: 0.59 | E7: 0.76 | F7: 0.82 | G7: 0.43 | H7: 0.97 | I7: 267 | J7: 11 | K7: 0.69 | L7: Medium
A8: 34 | B8: 2022 | C8: 0.93 | D8: 0.76 | E8: 0.96 | F8: 0.64 | G8: 0.44 | H8: 0.05 | I8: 345 | J8: 15 | K8: 0.8 | L8: High
A9: 82 | B9: 2025 | C9: 0.71 | D9: 0.98 | E9: 0.8 | F9: 0.71 | G9: 0.51 | H9: 0.17 | I9: 394 | J9: 6 | K9: 0.78 | L9: High
A10: 9 | B10: 2021 | C10: 0.44 | D10: 0.4 | E10: 0.91 | F10: 0.88 | G10: 0.81 | H10: 0.77 | I10: 310 | J10: 9 | K10: 0.63 | L10: Medium
A11: 41 | B11: 2024 | C11: 0.9 | D11: 0.77 | E11: 0.67 | F11: 0.63 | G11: 0.52 | H11: 0.33 | I11: 148 | J11: 11 | K11: 0.74 | L11: High
A12: 86 | B12: 2023 | C12: 0.69 | D12: 0.63 | E12: 0.99 | F12: 0.94 | G12: 0.81 | H12: 0.24 | I12: 447 | J12: 6 | K12: 0.78 | L12: High
A13: 27 | B13: 2021 | C13: 0.8 | D13: 0.47 | E13: 0.72 | F13: 0.68 | G13: 0.93 | H13: 0.48 | I13: 145 | J13: 3 | K13: 0.7 | L13: Medium
... A1801: 10 | B1801: 2021 | C1801: 0.4 | D1801: 0.67 | E1801: 0.59 | F1801: 0.86 | G1801: 0.41 | H1801: 0.9 | I1801: 373 | J1801: 1 | K1801: 0.58 | L1801: Medium

Sheet Seller_Risk_Analysis
A1: Seller_ID | B1: Analysis_Year | C1: Total_Orders | D1: Returned_Orders | E1: Refund_Requests | F1: Refund_Amount | G1: Refund_Rate | H1: User_Reports_Count | I1: Negative_Review_Count | J1: Customer_Dispute_Count | K1: Policy_Violation_Count | L1: Fraud_Flag | M1: Fraud_Review_Count | N1: Escalation_Count | O1: Chargeback_Count | P1: Governance_Action_Status | Q1: Seller_Name | R1: Primary_Category | S1: Region | T1: Marketplace_Tier | U1: Onboarding_Date | V1: Violation_Count | W1: Total_Penalty_Amount | X1: Fraud_Linked_Violation_Count | Y1: Resolved_Violation_Count | Z1: Unresolved_Violation_Count | AA1: Critical_High_Severity_Count | AB1: Escalated_Open_Violation_Count | AC1: Affected_Order_Total | AD1: Seller_Year_Key | AE1: Refund_Risk_Flag | AF1: User_Report_Risk_Flag | AG1: Violation_Severity_Flag | AH1: Fraud_Concern_Flag | AI1: Governance_Action_Severity_Flag | AJ1: Overall_Risk_Score | AK1: Final_Seller_Risk
A2: 1 | B2: 2021 | C2: 1639 | D2: 93 | E2: 72 | F2: 4476.59 | G2: 0.043929 | H2: 12 | I2: 33 | J2: 11 | K2: 7 | L2: 1 | M2: 4 | N2: 4 | O2: 3 | P2: Suspended | Q2: =VLOOKUP(A2,Cleaned_Seller_Master!$A:$H,2,FALSE) -> Swift Goods 001 | R2: =VLOOKUP(A2,Cleaned_Seller_Master!$A:$H,4,FALSE) -> Electronics | S2: =VLOOKUP(A2,Cleaned_Seller_Master!$A:$H,5,FALSE) -> Southeast Asia | T2: =VLOOKUP(A2,Cleaned_Seller_Master!$A:$H,8,FALSE) -> Standard | U2: =VLOOKUP(A2,Cleaned_Seller_Master!$A:$H,7,FALSE) -> 01-01-2023 | V2: =IFERROR(INDEX(Violation_Summary_Seller_Year!$C:$C,MATCH(AD2,Violation_Summary_Seller_Year!$K:$K,0)),0) -> 2 | W2: =IFERROR(INDEX(Violation_Summary_Seller_Year!$D:$D,MATCH(AD2,Violation_Summary_Seller_Year!$K:$K,0)),0) -> 3866.18 | X2: =IFERROR(INDEX(Violation_Summary_Seller_Year!$E:$E,MATCH(AD2,Violation_Summary_Seller_Year!$K:$K,0)),0) -> 1 | Y2: =IFERROR(INDEX(Violation_Summary_Seller_Year!$F:$F,MATCH(AD2,Violation_Summary_Seller_Year!$K:$K,0)),0) -> 0 | Z2: =IFERROR(INDEX(Violation_Summary_Seller_Year!$G:$G,MATCH(AD2,Violation_Summary_Seller_Year!$K:$K,0)),0) -> 2 | AA2: =IFERROR(INDEX(Violation_Summary_Seller_Year!$H:$H,MATCH(AD2,Violation_Summary_Seller_Year!$K:$K,0)),0) -> 2 | AB2: =IFERROR(INDEX(Violation_Summary_Seller_Year!$I:$I,MATCH(AD2,Violation_Summary_Seller_Year!$K:$K,0)),0) -> 2 | AC2: =IFERROR(INDEX(Violation_Summary_Seller_Year!$J:$J,MATCH(AD2,Violation_Summary_Seller_Year!$K:$K,0)),0) -> 21 | AD2: =A2&"_"&B2 -> 1_2021 | AE2: =IF(G2>=0.1,2,IF(G2>=0.05,1,0)) -> 0 | AF2: =IF(H2>=8,2,IF(H2>=4,1,0)) -> 2 | AG2: =IF(OR(AA2>=2,V2>=5),2,IF(OR(AA2>=1,V2>=2),1,0)) -> 2 | AH2: =IF(OR(L2=1,X2>=2),2,IF(X2>=1,1,0)) -> 2 | AI2: =IF(OR(P2="Suspended",P2="Blocked"),2,IF(OR(P2="Under Review",P2="Warning",P2="Review Required",P2="Restricted",P2="Watchlist"),1,0)) -> 2 | AJ2: =(AE2*25)+(AF2*25)+(AG2*20)+(AH2*20)+(AI2*10) -> 150 | AK2: =IF(AJ2>=120,"High",IF(AJ2>=60,"Medium","Low")) -> High
A3: 2 | B3: 2021 | C3: 2638 | D3: 254 | E3: 224 | F3: 9826.34 | G3: 0.084913 | H3: 26 | I3: 83 | J3: 21 | K3: 11 | L3: 1 | M3: 4 | N3: 5 | O3: 8 | P3: Suspended | Q3: =VLOOKUP(A3,Cleaned_Seller_Master!$A:$H,2,FALSE) -> Blue Source 002 | R3: =VLOOKUP(A3,Cleaned_Seller_Master!$A:$H,4,FALSE) -> Home | S3: =VLOOKUP(A3,Cleaned_Seller_Master!$A:$H,5,FALSE) -> South | T3: =VLOOKUP(A3,Cleaned_Seller_Master!$A:$H,8,FALSE) -> Verified | U3: =VLOOKUP(A3,Cleaned_Seller_Master!$A:$H,7,FALSE) -> 25-01-2022 | V3: =IFERROR(INDEX(Violation_Summary_Seller_Year!$C:$C,MATCH(AD3,Violation_Summary_Seller_Year!$K:$K,0)),0) -> 6 | W3: =IFERROR(INDEX(Violation_Summary_Seller_Year!$D:$D,MATCH(AD3,Violation_Summary_Seller_Year!$K:$K,0)),0) -> 9238.55 | X3: =IFERROR(INDEX(Violation_Summary_Seller_Year!$E:$E,MATCH(AD3,Violation_Summary_Seller_Year!$K:$K,0)),0) -> 5 | Y3: =IFERROR(INDEX(Violation_Summary_Seller_Year!$F:$F,MATCH(AD3,Violation_Summary_Seller_Year!$K:$K,0)),0) -> 5 | Z3: =IFERROR(INDEX(Violation_Summary_Seller_Year!$G:$G,MATCH(AD3,Violation_Summary_Seller_Year!$K:$K,0)),0) -> 1 | AA3: =IFERROR(INDEX(Violation_Summary_Seller_Year!$H:$H,MATCH(AD3,Violation_Summary_Seller_Year!$K:$K,0)),0) -> 3 | AB3: =IFERROR(INDEX(Violation_Summary_Seller_Year!$I:$I,MATCH(AD3,Violation_Summary_Seller_Year!$K:$K,0)),0) -> 2 | AC3: =IFERROR(INDEX(Violation_Summary_Seller_Year!$J:$J,MATCH(AD3,Violation_Summary_Seller_Year!$K:$K,0)),0) -> 80 | AD3: =A3&"_"&B3 -> 2_2021 | AE3: =IF(G3>=0.1,2,IF(G3>=0.05,1,0)) -> 1 | AF3: =IF(H3>=8,2,IF(H3>=4,1,0)) -> 2 | AG3: =IF(OR(AA3>=2,V3>=5),2,IF(OR(AA3>=1,V3>=2),1,0)) -> 2 | AH3: =IF(OR(L3=1,X3>=2),2,IF(X3>=1,1,0)) -> 2 | AI3: =IF(OR(P3="Suspended",P3="Blocked"),2,IF(OR(P3="Under Review",P3="Warning",P3="Review Required",P3="Restricted",P3="Watchlist"),1,0)) -> 2 | AJ3: =(AE3*25)+(AF3*25)+(AG3*20)+(AH3*20)+(AI3*10) -> 175 | AK3: =IF(AJ3>=120,"High",IF(AJ3>=60,"Medium","Low")) -> High
A4: 3 | B4: 2021 | C4: 747 | D4: 70 | E4: 61 | F4: 4657.6 | G4: 0.08166 | H4: 20 | I4: 25 | J4: 14 | K4: 12 | L4: 1 | M4: 7 | N4: 6 | O4: 2 | P4: Suspended | Q4: =VLOOKUP(A4,Cleaned_Seller_Master!$A:$H,2,FALSE) -> Vertex Supply 003 | R4: =VLOOKUP(A4,Cleaned_Seller_Master!$A:$H,4,FALSE) -> Electronics | S4: =VLOOKUP(A4,Cleaned_Seller_Master!$A:$H,5,FALSE) -> West | T4: =VLOOKUP(A4,Cleaned_Seller_Master!$A:$H,8,FALSE) -> Standard | U4: =VLOOKUP(A4,Cleaned_Seller_Master!$A:$H,7,FALSE) -> 20-06-2023 | V4: =IFERROR(INDEX(Violation_Summary_Seller_Year!$C:$C,MATCH(AD4,Violation_Summary_Seller_Year!$K:$K,0)),0) -> 6 | W4: =IFERROR(INDEX(Violation_Summary_Seller_Year!$D:$D,MATCH(AD4,Violation_Summary_Seller_Year!$K:$K,0)),0) -> 17324.54 | X4: =IFERROR(INDEX(Violation_Summary_Seller_Year!$E:$E,MATCH(AD4,Violation_Summary_Seller_Year!$K:$K,0)),0) -> 4 | Y4: =IFERROR(INDEX(Violation_Summary_Seller_Year!$F:$F,MATCH(AD4,Violation_Summary_Seller_Year!$K:$K,0)),0) -> 3 | Z4: =IFERROR(INDEX(Violation_Summary_Seller_Year!$G:$G,MATCH(AD4,Violation_Summary_Seller_Year!$K:$K,0)),0) -> 3 | AA4: =IFERROR(INDEX(Violation_Summary_Seller_Year!$H:$H,MATCH(AD4,Violation_Summary_Seller_Year!$K:$K,0)),0) -> 6 | AB4: =IFERROR(INDEX(Violation_Summary_Seller_Year!$I:$I,MATCH(AD4,Violation_Summary_Seller_Year!$K:$K,0)),0) -> 5 | AC4: =IFERROR(INDEX(Violation_Summary_Seller_Year!$J:$J,MATCH(AD4,Violation_Summary_Seller_Year!$K:$K,0)),0) -> 47 | AD4: =A4&"_"&B4 -> 3_2021 | AE4: =IF(G4>=0.1,2,IF(G4>=0.05,1,0)) -> 1 | AF4: =IF(H4>=8,2,IF(H4>=4,1,0)) -> 2 | AG4: =IF(OR(AA4>=2,V4>=5),2,IF(OR(AA4>=1,V4>=2),1,0)) -> 2 | AH4: =IF(OR(L4=1,X4>=2),2,IF(X4>=1,1,0)) -> 2 | AI4: =IF(OR(P4="Suspended",P4="Blocked"),2,IF(OR(P4="Under Review",P4="Warning",P4="Review Required",P4="Restricted",P4="Watchlist"),1,0)) -> 2 | AJ4: =(AE4*25)+(AF4*25)+(AG4*20)+(AH4*20)+(AI4*10) -> 175 | AK4: =IF(AJ4>=120,"High",IF(AJ4>=60,"Medium","Low")) -> High
A5: 4 | B5: 2021 | C5: 480 | D5: 41 | E5: 36 | F5: 2011.28 | G5: 0.075 | H5: 19 | I5: 19 | J5: 9 | K5: 8 | L5: 1 | M5: 6 | N5: 6 | O5: 5 | P5: Suspended | Q5: =VLOOKUP(A5,Cleaned_Seller_Master!$A:$H,2,FALSE) -> Zen Mart 004 | R5: =VLOOKUP(A5,Cleaned_Seller_Master!$A:$H,4,FALSE) -> Fashion | S5: =VLOOKUP(A5,Cleaned_Seller_Master!$A:$H,5,FALSE) -> Southeast Asia | T5: =VLOOKUP(A5,Cleaned_Seller_Master!$A:$H,8,FALSE) -> Standard | U5: =VLOOKUP(A5,Cleaned_Seller_Master!$A:$H,7,FALSE) -> 03-12-2021 | V5: =IFERROR(INDEX(Violation_Summary_Seller_Year!$C:$C,MATCH(AD5,Violation_Summary_Seller_Year!$K:$K,0)),0) -> 5 | W5: =IFERROR(INDEX(Violation_Summary_Seller_Year!$D:$D,MATCH(AD5,Violation_Summary_Seller_Year!$K:$K,0)),0) -> 17378.91 | X5: =IFERROR(INDEX(Violation_Summary_Seller_Year!$E:$E,MATCH(AD5,Violation_Summary_Seller_Year!$K:$K,0)),0) -> 3 | Y5: =IFERROR(INDEX(Violation_Summary_Seller_Year!$F:$F,MATCH(AD5,Violation_Summary_Seller_Year!$K:$K,0)),0) -> 2 | Z5: =IFERROR(INDEX(Violation_Summary_Seller_Year!$G:$G,MATCH(AD5,Violation_Summary_Seller_Year!$K:$K,0)),0) -> 3 | AA5: =IFERROR(INDEX(Violation_Summary_Seller_Year!$H:$H,MATCH(AD5,Violation_Summary_Seller_Year!$K:$K,0)),0) -> 5 | AB5: =IFERROR(INDEX(Violation_Summary_Seller_Year!$I:$I,MATCH(AD5,Violation_Summary_Seller_Year!$K:$K,0)),0) -> 3 | AC5: =IFERROR(INDEX(Violation_Summary_Seller_Year!$J:$J,MATCH(AD5,Violation_Summary_Seller_Year!$K:$K,0)),0) -> 48 | AD5: =A5&"_"&B5 -> 4_2021 | AE5: =IF(G5>=0.1,2,IF(G5>=0.05,1,0)) -> 1 | AF5: =IF(H5>=8,2,IF(H5>=4,1,0)) -> 2 | AG5: =IF(OR(AA5>=2,V5>=5),2,IF(OR(AA5>=1,V5>=2),1,0)) -> 2 | AH5: =IF(OR(L5=1,X5>=2),2,IF(X5>=1,1,0)) -> 2 | AI5: =IF(OR(P5="Suspended",P5="Blocked"),2,IF(OR(P5="Under Review",P5="Warning",P5="Review Required",P5="Restricted",P5="Watchlist"),1,0)) -> 2 | AJ5: =(AE5*25)+(AF5*25)+(AG5*20)+(AH5*20)+(AI5*10) -> 175 | AK5: =IF(AJ5>=120,"High",IF(AJ5>=60,"Medium","Low")) -> High
A6: 5 | B6: 2021 | C6: 80 | D6: 9 | E6: 7 | F6: 570.73 | G6: 0.0875 | H6: 13 | I6: 13 | J6: 4 | K6: 5 | L6: 1 | M6: 4 | N6: 3 | O6: 2 | P6: Suspended | Q6: =VLOOKUP(A6,Cleaned_Seller_Master!$A:$H,2,FALSE) -> True House 005 | R6: =VLOOKUP(A6,Cleaned_Seller_Master!$A:$H,4,FALSE) -> Fashion | S6: =VLOOKUP(A6,Cleaned_Seller_Master!$A:$H,5,FALSE) -> West | T6: =VLOOKUP(A6,Cleaned_Seller_Master!$A:$H,8,FALSE) -> Standard | U6: =VLOOKUP(A6,Cleaned_Seller_Master!$A:$H,7,FALSE) -> 12-06-2020 | V6: =IFERROR(INDEX(Violation_Summary_Seller_Year!$C:$C,MATCH(AD6,Violation_Summary_Seller_Year!$K:$K,0)),0) -> 4 | W6: =IFERROR(INDEX(Violation_Summary_Seller_Year!$D:$D,MATCH(AD6,Violation_Summary_Seller_Year!$K:$K,0)),0) -> 11543.59 | X6: =IFERROR(INDEX(Violation_Summary_Seller_Year!$E:$E,MATCH(AD6,Violation_Summary_Seller_Year!$K:$K,0)),0) -> 2 | Y6: =IFERROR(INDEX(Violation_Summary_Seller_Year!$F:$F,MATCH(AD6,Violation_Summary_Seller_Year!$K:$K,0)),0) -> 3 | Z6: =IFERROR(INDEX(Violation_Summary_Seller_Year!$G:$G,MATCH(AD6,Violation_Summary_Seller_Year!$K:$K,0)),0) -> 1 | AA6: =IFERROR(INDEX(Violation_Summary_Seller_Year!$H:$H,MATCH(AD6,Violation_Summary_Seller_Year!$K:$K,0)),0) -> 3 | AB6: =IFERROR(INDEX(Violation_Summary_Seller_Year!$I:$I,MATCH(AD6,Violation_Summary_Seller_Year!$K:$K,0)),0) -> 0 | AC6: =IFERROR(INDEX(Violation_Summary_Seller_Year!$J:$J,MATCH(AD6,Violation_Summary_Seller_Year!$K:$K,0)),0) -> 43 | AD6: =A6&"_"&B6 -> 5_2021 | AE6: =IF(G6>=0.1,2,IF(G6>=0.05,1,0)) -> 1 | AF6: =IF(H6>=8,2,IF(H6>=4,1,0)) -> 2 | AG6: =IF(OR(AA6>=2,V6>=5),2,IF(OR(AA6>=1,V6>=2),1,0)) -> 2 | AH6: =IF(OR(L6=1,X6>=2),2,IF(X6>=1,1,0)) -> 2 | AI6: =IF(OR(P6="Suspended",P6="Blocked"),2,IF(OR(P6="Under Review",P6="Warning",P6="Review Required",P6="Restricted",P6="Watchlist"),1,0)) -> 2 | AJ6: =(AE6*25)+(AF6*25)+(AG6*20)+(AH6*20)+(AI6*10) -> 175 | AK6: =IF(AJ6>=120,"High",IF(AJ6>=60,"Medium","Low")) -> High
A7: 6 | B7: 2021 | C7: 881 | D7: 51 | E7: 46 | F7: 1423.51 | G7: 0.052213 | H7: 14 | I7: 24 | J7: 7 | K7: 9 | L7: 0 | M7: 3 | N7: 4 | O7: 3 | P7: Review Required | Q7: =VLOOKUP(A7,Cleaned_Seller_Master!$A:$H,2,FALSE) -> Core Traders 006 | R7: =VLOOKUP(A7,Cleaned_Seller_Master!$A:$H,4,FALSE) -> Beauty | S7: =VLOOKUP(A7,Cleaned_Seller_Master!$A:$H,5,FALSE) -> South | T7: =VLOOKUP(A7,Cleaned_Seller_Master!$A:$H,8,FALSE) -> Premium | U7: =VLOOKUP(A7,Cleaned_Seller_Master!$A:$H,7,FALSE) -> 21-05-2023 | V7: =IFERROR(INDEX(Violation_Summary_Seller_Year!$C:$C,MATCH(AD7,Violation_Summary_Seller_Year!$K:$K,0)),0) -> 2 | W7: =IFERROR(INDEX(Violation_Summary_Seller_Year!$D:$D,MATCH(AD7,Violation_Summary_Seller_Year!$K:$K,0)),0) -> 1782.84 | X7: =IFERROR(INDEX(Violation_Summary_Seller_Year!$E:$E,MATCH(AD7,Violation_Summary_Seller_Year!$K:$K,0)),0) -> 0 | Y7: =IFERROR(INDEX(Violation_Summary_Seller_Year!$F:$F,MATCH(AD7,Violation_Summary_Seller_Year!$K:$K,0)),0) -> 1 | Z7: =IFERROR(INDEX(Violation_Summary_Seller_Year!$G:$G,MATCH(AD7,Violation_Summary_Seller_Year!$K:$K,0)),0) -> 1 | AA7: =IFERROR(INDEX(Violation_Summary_Seller_Year!$H:$H,MATCH(AD7,Violation_Summary_Seller_Year!$K:$K,0)),0) -> 0 | AB7: =IFERROR(INDEX(Violation_Summary_Seller_Year!$I:$I,MATCH(AD7,Violation_Summary_Seller_Year!$K:$K,0)),0) -> 1 | AC7: =IFERROR(INDEX(Violation_Summary_Seller_Year!$J:$J,MATCH(AD7,Violation_Summary_Seller_Year!$K:$K,0)),0) -> 7 | AD7: =A7&"_"&B7 -> 6_2021 | AE7: =IF(G7>=0.1,2,IF(G7>=0.05,1,0)) -> 1 | AF7: =IF(H7>=8,2,IF(H7>=4,1,0)) -> 2 | AG7: =IF(OR(AA7>=2,V7>=5),2,IF(OR(AA7>=1,V7>=2),1,0)) -> 1 | AH7: =IF(OR(L7=1,X7>=2),2,IF(X7>=1,1,0)) -> 0 | AI7: =IF(OR(P7="Suspended",P7="Blocked"),2,IF(OR(P7="Under Review",P7="Warning",P7="Review Required",P7="Restricted",P7="Watchlist"),1,0)) -> 1 | AJ7: =(AE7*25)+(AF7*25)+(AG7*20)+(AH7*20)+(AI7*10) -> 105 | AK7: =IF(AJ7>=120,"High",IF(AJ7>=60,"Medium","Low")) -> Medium
A8: 7 | B8: 2021 | C8: 792 | D8: 69 | E8: 65 | F8: 6991.26 | G8: 0.082071 | H8: 30 | I8: 30 | J8: 13 | K8: 12 | L8: 1 | M8: 5 | N8: 7 | O8: 3 | P8: Suspended | Q8: =VLOOKUP(A8,Cleaned_Seller_Master!$A:$H,2,FALSE) -> Urban Works 007 | R8: =VLOOKUP(A8,Cleaned_Seller_Master!$A:$H,4,FALSE) -> Fashion | S8: =VLOOKUP(A8,Cleaned_Seller_Master!$A:$H,5,FALSE) -> West | T8: =VLOOKUP(A8,Cleaned_Seller_Master!$A:$H,8,FALSE) -> Premium | U8: =VLOOKUP(A8,Cleaned_Seller_Master!$A:$H,7,FALSE) -> 19-04-2018 | V8: =IFERROR(INDEX(Violation_Summary_Seller_Year!$C:$C,MATCH(AD8,Violation_Summary_Seller_Year!$K:$K,0)),0) -> 4 | W8: =IFERROR(INDEX(Violation_Summary_Seller_Year!$D:$D,MATCH(AD8,Violation_Summary_Seller_Year!$K:$K,0)),0) -> 16370.74 | X8: =IFERROR(INDEX(Violation_Summary_Seller_Year!$E:$E,MATCH(AD8,Violation_Summary_Seller_Year!$K:$K,0)),0) -> 1 | Y8: =IFERROR(INDEX(Violation_Summary_Seller_Year!$F:$F,MATCH(AD8,Violation_Summary_Seller_Year!$K:$K,0)),0) -> 2 | Z8: =IFERROR(INDEX(Violation_Summary_Seller_Year!$G:$G,MATCH(AD8,Violation_Summary_Seller_Year!$K:$K,0)),0) -> 2 | AA8: =IFERROR(INDEX(Violation_Summary_Seller_Year!$H:$H,MATCH(AD8,Violation_Summary_Seller_Year!$K:$K,0)),0) -> 4 | AB8: =IFERROR(INDEX(Violation_Summary_Seller_Year!$I:$I,MATCH(AD8,Violation_Summary_Seller_Year!$K:$K,0)),0) -> 2 | AC8: =IFERROR(INDEX(Violation_Summary_Seller_Year!$J:$J,MATCH(AD8,Violation_Summary_Seller_Year!$K:$K,0)),0) -> 35 | AD8: =A8&"_"&B8 -> 7_2021 | AE8: =IF(G8>=0.1,2,IF(G8>=0.05,1,0)) -> 1 | AF8: =IF(H8>=8,2,IF(H8>=4,1,0)) -> 2 | AG8: =IF(OR(AA8>=2,V8>=5),2,IF(OR(AA8>=1,V8>=2),1,0)) -> 2 | AH8: =IF(OR(L8=1,X8>=2),2,IF(X8>=1,1,0)) -> 2 | AI8: =IF(OR(P8="Suspended",P8="Blocked"),2,IF(OR(P8="Under Review",P8="Warning",P8="Review Required",P8="Restricted",P8="Watchlist"),1,0)) -> 2 | AJ8: =(AE8*25)+(AF8*25)+(AG8*20)+(AH8*20)+(AI8*10) -> 175 | AK8: =IF(AJ8>=120,"High",IF(AJ8>=60,"Medium","Low")) -> High
A9: 8 | B9: 2021 | C9: 575 | D9: 47 | E9: 38 | F9: 2474.85 | G9: 0.066087 | H9: 8 | I9: 16 | J9: 8 | K9: 5 | L9: 1 | M9: 5 | N9: 3 | O9: 4 | P9: Suspended | Q9: =VLOOKUP(A9,Cleaned_Seller_Master!$A:$H,2,FALSE) -> Bright Nest 008 | R9: =VLOOKUP(A9,Cleaned_Seller_Master!$A:$H,4,FALSE) -> Fashion | S9: =VLOOKUP(A9,Cleaned_Seller_Master!$A:$H,5,FALSE) -> South | T9: =VLOOKUP(A9,Cleaned_Seller_Master!$A:$H,8,FALSE) -> Verified | U9: =VLOOKUP(A9,Cleaned_Seller_Master!$A:$H,7,FALSE) -> 19-12-2021 | V9: =IFERROR(INDEX(Violation_Summary_Seller_Year!$C:$C,MATCH(AD9,Violation_Summary_Seller_Year!$K:$K,0)),0) -> 5 | W9: =IFERROR(INDEX(Violation_Summary_Seller_Year!$D:$D,MATCH(AD9,Violation_Summary_Seller_Year!$K:$K,0)),0) -> 11161.78 | X9: =IFERROR(INDEX(Violation_Summary_Seller_Year!$E:$E,MATCH(AD9,Violation_Summary_Seller_Year!$K:$K,0)),0) -> 3 | Y9: =IFERROR(INDEX(Violation_Summary_Seller_Year!$F:$F,MATCH(AD9,Violation_Summary_Seller_Year!$K:$K,0)),0) -> 1 | Z9: =IFERROR(INDEX(Violation_Summary_Seller_Year!$G:$G,MATCH(AD9,Violation_Summary_Seller_Year!$K:$K,0)),0) -> 4 | AA9: =IFERROR(INDEX(Violation_Summary_Seller_Year!$H:$H,MATCH(AD9,Violation_Summary_Seller_Year!$K:$K,0)),0) -> 4 | AB9: =IFERROR(INDEX(Violation_Summary_Seller_Year!$I:$I,MATCH(AD9,Violation_Summary_Seller_Year!$K:$K,0)),0) -> 4 | AC9: =IFERROR(INDEX(Violation_Summary_Seller_Year!$J:$J,MATCH(AD9,Violation_Summary_Seller_Year!$K:$K,0)),0) -> 37 | AD9: =A9&"_"&B9 -> 8_2021 | AE9: =IF(G9>=0.1,2,IF(G9>=0.05,1,0)) -> 1 | AF9: =IF(H9>=8,2,IF(H9>=4,1,0)) -> 2 | AG9: =IF(OR(AA9>=2,V9>=5),2,IF(OR(AA9>=1,V9>=2),1,0)) -> 2 | AH9: =IF(OR(L9=1,X9>=2),2,IF(X9>=1,1,0)) -> 2 | AI9: =IF(OR(P9="Suspended",P9="Blocked"),2,IF(OR(P9="Under Review",P9="Warning",P9="Review Required",P9="Restricted",P9="Watchlist"),1,0)) -> 2 | AJ9: =(AE9*25)+(AF9*25)+(AG9*20)+(AH9*20)+(AI9*10) -> 175 | AK9: =IF(AJ9>=120,"High",IF(AJ9>=60,"Medium","Low")) -> High
A10: 9 | B10: 2021 | C10: 892 | D10: 47 | E10: 38 | F10: 3271.85 | G10: 0.042601 | H10: 13 | I10: 24 | J10: 8 | K10: 3 | L10: 1 | M10: 2 | N10: 3 | O10: 3 | P10: Restricted | Q10: =VLOOKUP(A10,Cleaned_Seller_Master!$A:$H,2,FALSE) -> Golden Hub 009 | R10: =VLOOKUP(A10,Cleaned_Seller_Master!$A:$H,4,FALSE) -> Electronics | S10: =VLOOKUP(A10,Cleaned_Seller_Master!$A:$H,5,FALSE) -> North | T10: =VLOOKUP(A10,Cleaned_Seller_Master!$A:$H,8,FALSE) -> Strategic | U10: =VLOOKUP(A10,Cleaned_Seller_Master!$A:$H,7,FALSE) -> 14-11-2020 | V10: =IFERROR(INDEX(Violation_Summary_Seller_Year!$C:$C,MATCH(AD10,Violation_Summary_Seller_Year!$K:$K,0)),0) -> 1 | W10: =IFERROR(INDEX(Violation_Summary_Seller_Year!$D:$D,MATCH(AD10,Violation_Summary_Seller_Year!$K:$K,0)),0) -> 1102.52 | X10: =IFERROR(INDEX(Violation_Summary_Seller_Year!$E:$E,MATCH(AD10,Violation_Summary_Seller_Year!$K:$K,0)),0) -> 0 | Y10: =IFERROR(INDEX(Violation_Summary_Seller_Year!$F:$F,MATCH(AD10,Violation_Summary_Seller_Year!$K:$K,0)),0) -> 1 | Z10: =IFERROR(INDEX(Violation_Summary_Seller_Year!$G:$G,MATCH(AD10,Violation_Summary_Seller_Year!$K:$K,0)),0) -> 0 | AA10: =IFERROR(INDEX(Violation_Summary_Seller_Year!$H:$H,MATCH(AD10,Violation_Summary_Seller_Year!$K:$K,0)),0) -> 0 | AB10: =IFERROR(INDEX(Violation_Summary_Seller_Year!$I:$I,MATCH(AD10,Violation_Summary_Seller_Year!$K:$K,0)),0) -> 0 | AC10: =IFERROR(INDEX(Violation_Summary_Seller_Year!$J:$J,MATCH(AD10,Violation_Summary_Seller_Year!$K:$K,0)),0) -> 5 | AD10: =A10&"_"&B10 -> 9_2021 | AE10: =IF(G10>=0.1,2,IF(G10>=0.05,1,0)) -> 0 | AF10: =IF(H10>=8,2,IF(H10>=4,1,0)) -> 2 | AG10: =IF(OR(AA10>=2,V10>=5),2,IF(OR(AA10>=1,V10>=2),1,0)) -> 0 | AH10: =IF(OR(L10=1,X10>=2),2,IF(X10>=1,1,0)) -> 2 | AI10: =IF(OR(P10="Suspended",P10="Blocked"),2,IF(OR(P10="Under Review",P10="Warning",P10="Review Required",P10="Restricted",P10="Watchlist"),1,0)) -> 1 | AJ10: =(AE10*25)+(AF10*25)+(AG10*20)+(AH10*20)+(AI10*10) -> 100 | AK10: =IF(AJ10>=120,"High",IF(AJ10>=60,"Medium","Low")) -> Medium
A11: 10 | B11: 2021 | C11: 1054 | D11: 64 | E11: 49 | F11: 4827.25 | G11: 0.04649 | H11: 19 | I11: 23 | J11: 8 | K11: 9 | L11: 0 | M11: 3 | N11: 3 | O11: 4 | P11: Review Required | Q11: =VLOOKUP(A11,Cleaned_Seller_Master!$A:$H,2,FALSE) -> Ever Merchants 010 | R11: =VLOOKUP(A11,Cleaned_Seller_Master!$A:$H,4,FALSE) -> Electronics | S11: =VLOOKUP(A11,Cleaned_Seller_Master!$A:$H,5,FALSE) -> North | T11: =VLOOKUP(A11,Cleaned_Seller_Master!$A:$H,8,FALSE) -> Standard | U11: =VLOOKUP(A11,Cleaned_Seller_Master!$A:$H,7,FALSE) -> 11-11-2022 | V11: =IFERROR(INDEX(Violation_Summary_Seller_Year!$C:$C,MATCH(AD11,Violation_Summary_Seller_Year!$K:$K,0)),0) -> 2 | W11: =IFERROR(INDEX(Violation_Summary_Seller_Year!$D:$D,MATCH(AD11,Violation_Summary_Seller_Year!$K:$K,0)),0) -> 719.28 | X11: =IFERROR(INDEX(Violation_Summary_Seller_Year!$E:$E,MATCH(AD11,Violation_Summary_Seller_Year!$K:$K,0)),0) -> 0 | Y11: =IFERROR(INDEX(Violation_Summary_Seller_Year!$F:$F,MATCH(AD11,Violation_Summary_Seller_Year!$K:$K,0)),0) -> 2 | Z11: =IFERROR(INDEX(Violation_Summary_Seller_Year!$G:$G,MATCH(AD11,Violation_Summary_Seller_Year!$K:$K,0)),0) -> 0 | AA11: =IFERROR(INDEX(Violation_Summary_Seller_Year!$H:$H,MATCH(AD11,Violation_Summary_Seller_Year!$K:$K,0)),0) -> 0 | AB11: =IFERROR(INDEX(Violation_Summary_Seller_Year!$I:$I,MATCH(AD11,Violation_Summary_Seller_Year!$K:$K,0)),0) -> 0 | AC11: =IFERROR(INDEX(Violation_Summary_Seller_Year!$J:$J,MATCH(AD11,Violation_Summary_Seller_Year!$K:$K,0)),0) -> 8 | AD11: =A11&"_"&B11 -> 10_2021 | AE11: =IF(G11>=0.1,2,IF(G11>=0.05,1,0)) -> 0 | AF11: =IF(H11>=8,2,IF(H11>=4,1,0)) -> 2 | AG11: =IF(OR(AA11>=2,V11>=5),2,IF(OR(AA11>=1,V11>=2),1,0)) -> 1 | AH11: =IF(OR(L11=1,X11>=2),2,IF(X11>=1,1,0)) -> 0 | AI11: =IF(OR(P11="Suspended",P11="Blocked"),2,IF(OR(P11="Under Review",P11="Warning",P11="Review Required",P11="Restricted",P11="Watchlist"),1,0)) -> 1 | AJ11: =(AE11*25)+(AF11*25)+(AG11*20)+(AH11*20)+(AI11*10) -> 80 | AK11: =IF(AJ11>=120,"High",IF(AJ11>=60,"Medium","Low")) -> Medium
A12: 12 | B12: 2021 | C12: 1863 | D12: 169 | E12: 126 | F12: 5399.95 | G12: 0.067633 | H12: 41 | I12: 61 | J12: 13 | K12: 21 | L12: 1 | M12: 6 | N12: 9 | O12: 6 | P12: Suspended | Q12: =VLOOKUP(A12,Cleaned_Seller_Master!$A:$H,2,FALSE) -> Pulse Commerce 012 | R12: =VLOOKUP(A12,Cleaned_Seller_Master!$A:$H,4,FALSE) -> Groceries | S12: =VLOOKUP(A12,Cleaned_Seller_Master!$A:$H,5,FALSE) -> North | T12: =VLOOKUP(A12,Cleaned_Seller_Master!$A:$H,8,FALSE) -> Verified | U12: =VLOOKUP(A12,Cleaned_Seller_Master!$A:$H,7,FALSE) -> 01-08-2023 | V12: =IFERROR(INDEX(Violation_Summary_Seller_Year!$C:$C,MATCH(AD12,Violation_Summary_Seller_Year!$K:$K,0)),0) -> 5 | W12: =IFERROR(INDEX(Violation_Summary_Seller_Year!$D:$D,MATCH(AD12,Violation_Summary_Seller_Year!$K:$K,0)),0) -> 16001.04 | X12: =IFERROR(INDEX(Violation_Summary_Seller_Year!$E:$E,MATCH(AD12,Violation_Summary_Seller_Year!$K:$K,0)),0) -> 3 | Y12: =IFERROR(INDEX(Violation_Summary_Seller_Year!$F:$F,MATCH(AD12,Violation_Summary_Seller_Year!$K:$K,0)),0) -> 2 | Z12: =IFERROR(INDEX(Violation_Summary_Seller_Year!$G:$G,MATCH(AD12,Violation_Summary_Seller_Year!$K:$K,0)),0) -> 3 | AA12: =IFERROR(INDEX(Violation_Summary_Seller_Year!$H:$H,MATCH(AD12,Violation_Summary_Seller_Year!$K:$K,0)),0) -> 5 | AB12: =IFERROR(INDEX(Violation_Summary_Seller_Year!$I:$I,MATCH(AD12,Violation_Summary_Seller_Year!$K:$K,0)),0) -> 2 | AC12: =IFERROR(INDEX(Violation_Summary_Seller_Year!$J:$J,MATCH(AD12,Violation_Summary_Seller_Year!$K:$K,0)),0) -> 50 | AD12: =A12&"_"&B12 -> 12_2021 | AE12: =IF(G12>=0.1,2,IF(G12>=0.05,1,0)) -> 1 | AF12: =IF(H12>=8,2,IF(H12>=4,1,0)) -> 2 | AG12: =IF(OR(AA12>=2,V12>=5),2,IF(OR(AA12>=1,V12>=2),1,0)) -> 2 | AH12: =IF(OR(L12=1,X12>=2),2,IF(X12>=1,1,0)) -> 2 | AI12: =IF(OR(P12="Suspended",P12="Blocked"),2,IF(OR(P12="Under Review",P12="Warning",P12="Review Required",P12="Restricted",P12="Watchlist"),1,0)) -> 2 | AJ12: =(AE12*25)+(AF12*25)+(AG12*20)+(AH12*20)+(AI12*10) -> 175 | AK12: =IF(AJ12>=120,"High",IF(AJ12>=60,"Medium","Low")) -> High
A13: 13 | B13: 2021 | C13: 241 | D13: 24 | E13: 19 | F13: 2150.92 | G13: 0.078838 | H13: 15 | I13: 16 | J13: 7 | K13: 6 | L13: 0 | M13: 1 | N13: 4 | O13: 1 | P13: Suspended | Q13: =VLOOKUP(A13,Cleaned_Seller_Master!$A:$H,2,FALSE) -> Summit Bazaar 013 | R13: =VLOOKUP(A13,Cleaned_Seller_Master!$A:$H,4,FALSE) -> Groceries | S13: =VLOOKUP(A13,Cleaned_Seller_Master!$A:$H,5,FALSE) -> North | T13: =VLOOKUP(A13,Cleaned_Seller_Master!$A:$H,8,FALSE) -> Premium | U13: =VLOOKUP(A13,Cleaned_Seller_Master!$A:$H,7,FALSE) -> 25-02-2025 | V13: =IFERROR(INDEX(Violation_Summary_Seller_Year!$C:$C,MATCH(AD13,Violation_Summary_Seller_Year!$K:$K,0)),0) -> 6 | W13: =IFERROR(INDEX(Violation_Summary_Seller_Year!$D:$D,MATCH(AD13,Violation_Summary_Seller_Year!$K:$K,0)),0) -> 21731.77 | X13: =IFERROR(INDEX(Violation_Summary_Seller_Year!$E:$E,MATCH(AD13,Violation_Summary_Seller_Year!$K:$K,0)),0) -> 0 | Y13: =IFERROR(INDEX(Violation_Summary_Seller_Year!$F:$F,MATCH(AD13,Violation_Summary_Seller_Year!$K:$K,0)),0) -> 2 | Z13: =IFERROR(INDEX(Violation_Summary_Seller_Year!$G:$G,MATCH(AD13,Violation_Summary_Seller_Year!$K:$K,0)),0) -> 4 | AA13: =IFERROR(INDEX(Violation_Summary_Seller_Year!$H:$H,MATCH(AD13,Violation_Summary_Seller_Year!$K:$K,0)),0) -> 5 | AB13: =IFERROR(INDEX(Violation_Summary_Seller_Year!$I:$I,MATCH(AD13,Violation_Summary_Seller_Year!$K:$K,0)),0) -> 2 | AC13: =IFERROR(INDEX(Violation_Summary_Seller_Year!$J:$J,MATCH(AD13,Violation_Summary_Seller_Year!$K:$K,0)),0) -> 65 | AD13: =A13&"_"&B13 -> 13_2021 | AE13: =IF(G13>=0.1,2,IF(G13>=0.05,1,0)) -> 1 | AF13: =IF(H13>=8,2,IF(H13>=4,1,0)) -> 2 | AG13: =IF(OR(AA13>=2,V13>=5),2,IF(OR(AA13>=1,V13>=2),1,0)) -> 2 | AH13: =IF(OR(L13=1,X13>=2),2,IF(X13>=1,1,0)) -> 0 | AI13: =IF(OR(P13="Suspended",P13="Blocked"),2,IF(OR(P13="Under Review",P13="Warning",P13="Review Required",P13="Restricted",P13="Watchlist"),1,0)) -> 2 | AJ13: =(AE13*25)+(AF13*25)+(AG13*20)+(AH13*20)+(AI13*10) -> 135 | AK13: =IF(AJ13>=120,"High",IF(AJ13>=60,"Medium","Low")) -> High
... A480: 100 | B480: 2025 | C480: 1277 | D480: 141 | E480: 116 | F480: 7559.22 | G480: 0.090838 | H480: 36 | I480: 50 | J480: 26 | K480: 21 | L480: 0 | M480: 3 | N480: 9 | O480: 8 | P480: Restricted | Q480: =VLOOKUP(A480,Cleaned_Seller_Master!$A:$H,2,FALSE) -> Nova Cart 100 | R480: =VLOOKUP(A480,Cleaned_Seller_Master!$A:$H,4,FALSE) -> Groceries | S480: =VLOOKUP(A480,Cleaned_Seller_Master!$A:$H,5,FALSE) -> Southeast Asia | T480: =VLOOKUP(A480,Cleaned_Seller_Master!$A:$H,8,FALSE) -> Verified | U480: =VLOOKUP(A480,Cleaned_Seller_Master!$A:$H,7,FALSE) -> 04-12-2018 | V480: =IFERROR(INDEX(Violation_Summary_Seller_Year!$C:$C,MATCH(AD480,Violation_Summary_Seller_Year!$K:$K,0)),0) -> 5 | W480: =IFERROR(INDEX(Violation_Summary_Seller_Year!$D:$D,MATCH(AD480,Violation_Summary_Seller_Year!$K:$K,0)),0) -> 8908.72 | X480: =IFERROR(INDEX(Violation_Summary_Seller_Year!$E:$E,MATCH(AD480,Violation_Summary_Seller_Year!$K:$K,0)),0) -> 0 | Y480: =IFERROR(INDEX(Violation_Summary_Seller_Year!$F:$F,MATCH(AD480,Violation_Summary_Seller_Year!$K:$K,0)),0) -> 2 | Z480: =IFERROR(INDEX(Violation_Summary_Seller_Year!$G:$G,MATCH(AD480,Violation_Summary_Seller_Year!$K:$K,0)),0) -> 3 | AA480: =IFERROR(INDEX(Violation_Summary_Seller_Year!$H:$H,MATCH(AD480,Violation_Summary_Seller_Year!$K:$K,0)),0) -> 3 | AB480: =IFERROR(INDEX(Violation_Summary_Seller_Year!$I:$I,MATCH(AD480,Violation_Summary_Seller_Year!$K:$K,0)),0) -> 2 | AC480: =IFERROR(INDEX(Violation_Summary_Seller_Year!$J:$J,MATCH(AD480,Violation_Summary_Seller_Year!$K:$K,0)),0) -> 27 | AD480: =A480&"_"&B480 -> 100_2025 | AE480: =IF(G480>=0.1,2,IF(G480>=0.05,1,0)) -> 1 | AF480: =IF(H480>=8,2,IF(H480>=4,1,0)) -> 2 | AG480: =IF(OR(AA480>=2,V480>=5),2,IF(OR(AA480>=1,V480>=2),1,0)) -> 2 | AH480: =IF(OR(L480=1,X480>=2),2,IF(X480>=1,1,0)) -> 0 | AI480: =IF(OR(P480="Suspended",P480="Blocked"),2,IF(OR(P480="Under Review",P480="Warning",P480="Review Required",P480="Restricted",P480="Watchlist"),1,0)) -> 1 | AJ480: =(AE480*25)+(AF480*25)+(AG480*20)+(AH480*20)+(AI480*10) -> 125 | AK480: =IF(AJ480>=120,"High",IF(AJ480>=60,"Medium","Low")) -> High

Sheet Pivot_Risk_Reports
A1: Seller Count by Final Risk Level
A2: Analysis_Year | B2: 2021 | H2: Risk Breakdown by Region
H3: Analysis_Year | I3: 2021
A4: Final_Seller_Risk | B4: Count of Seller_ID
A5: High | B5: 45 | H5: Count of Seller_ID | I5: Final_Seller_Risk
A6: Low | B6: 8 | H6: Region | I6: High | J6: Low | K6: Medium | L6: Grand Total
A7: Medium | B7: 25 | H7: North | I7: 15 | J7: 1 | K7: 6 | L7: 22
A8: Grand Total | B8: 78 | H8: South | I8: 8 | J8: 1 | K8: 10 | L8: 19
H9: Southeast Asia | I9: 8 | J9: 2 | K9: 5 | L9: 15
H10: West | I10: 14 | J10: 4 | K10: 4 | L10: 22
H11: Grand Total | I11: 45 | J11: 8 | K11: 25 | L11: 78
A12: Risk Breakdown by Primary Category
A13: Analysis_Year | B13: 2021
A15: Count of Seller_ID | B15: Final_Seller_Risk | J15: Top Risky Sellers by Average Risk Score
A16: Primary_Category | B16: High | C16: Low | D16: Medium | E16: Grand Total | J16: Final_Seller_Risk | K16: (All)
A17: Beauty | B17: 4 | C17: 2 | D17: 7 | E17: 13 | J17: Analysis_Year | K17: 2021
A18: Electronics | B18: 10 | C18: 1 | D18: 5 | E18: 16 | J18: Primary_Category | K18: (All)
A19: Fashion | B19: 11 | C19: 2 | D19: 4 | E19: 17
A20: Groceries | B20: 11 | C20: 3 | D20: 2 | E20: 16 | J20: Seller_Name | K20: Count of Seller_ID | L20: Average of Overall_Risk_Score
A21: Home | B21: 9 | D21: 7 | E21: 16 | J21: Golden Hub 049 | K21: 1 | L21: 200
A22: Grand Total | B22: 45 | C22: 8 | D22: 25 | E22: 78 | J22: Nova Cart 060 | K22: 1 | L22: 175
J23: Swift Goods 081 | K23: 1 | L23: 175
J24: Summit Bazaar 053 | K24: 1 | L24: 175
J25: Blue Source 002 | K25: 1 | L25: 175
A26: Category Risk Ranking by Average Risk Score | J26: Apex Retail 095 | K26: 1 | L26: 175
A27: Analysis_Year | B27: 2021 | J27: Blue Source 042 | K27: 1 | L27: 175
A28: Final_Seller_Risk | B28: (All) | J28: Pulse Commerce 012 | K28: 1 | L28: 175
J29: Bright Nest 008 | K29: 1 | L29: 175
A30: Primary_Category | B30: Average of Seller_ID | C30: Average of Overall_Risk_Score | J30: Summit Bazaar 093 | K30: 1 | L30: 175
A31: Fashion | B31: 47.647059 | C31: 137.05882 | J31: Ever Merchants 030 | K31: 1 | L31: 175
A32: Electronics | B32: 46.5 | C32: 134.0625 | J32: Urban Works 007 | K32: 1 | L32: 175
A33: Groceries | B33: 53.1875 | C33: 133.75 | J33: Zen Mart 004 | K33: 1 | L33: 175
A34: Home | B34: 47.3125 | C34: 129.0625 | J34: Zen Mart 064 | K34: 1 | L34: 175
A35: Beauty | B35: 52.538462 | C35: 104.23077 | J35: Nova Cart 040 | K35: 1 | L35: 175
A36: Grand Total | B36: 49.294872 | C36: 128.65385 | J36: Golden Hub 069 | K36: 1 | L36: 175
J37: Prime Bridge 034 | K37: 1 | L37: 175
J38: Golden Hub 089 | K38: 1 | L38: 175
J39: Pulse Commerce 072 | K39: 1 | L39: 175
J40: Luna Stores 018 | K40: 1 | L40: 175
J41: Summit Bazaar 073 | K41: 1 | L41: 175
...

Sheet Dashboard
I2: Risk Breakdown by Region
A3: E-Commerce Governance & Risk Dashboard | I3: Analysis_Year | J3: 2021
I5: Average of Overall_Risk_Score | J5: Column Labels
I6: Row Labels | J6: High | K6: Low | L6: Medium | M6: Grand Total
I7: North | J7: 151.66667 | K7: 35 | L7: 96.666667 | M7: 131.36364
I8: South | J8: 175.625 | K8: 55 | L8: 95 | M8: 126.84211
I9: Southeast Asia | J9: 159.375 | K9: 55 | L9: 94 | M9: 123.66667
I10: West | J10: 167.85714 | K10: 43.75 | L10: 88.75 | M10: 130.90909
I11: Grand Total | J11: 162.33333 | K11: 46.875 | L11: 94.2 | M11: 128.65385
B16: Seller Count by Risk Level | E16: Risk by Region
I17: Category Risk Ranking by Average Risk Score
I18: Analysis_Year | J18: 2021
I19: Final_Seller_Risk | J19: (All)
I21: Row Labels | J21: Average of Overall_Risk_Score | K21: Average of Seller_ID
I22: Fashion | J22: 137.05882 | K22: 47.647059
I23: Electronics | J23: 134.0625 | K23: 46.5
I24: Groceries | J24: 133.75 | K24: 53.1875
I25: Home | J25: 129.0625 | K25: 47.3125
I26: Beauty | J26: 104.23077 | K26: 52.538462
I27: Grand Total | J27: 128.65385 | K27: 49.294872
B32: Primary Category | F32: Primary Category
B34: Seller Count by Final Risk Level
B35: Analysis_Year | C35: 2021
B37: Row Labels | C37: Count of Seller_ID | E37: Top Risky Sellers by Average Risk Score
B38: High | C38: 45
B39: Low | C39: 8 | E39: Analysis_Year | F39: 2021
B40: Medium | C40: 25 | E40: Final_Seller_Risk | F40: (All)
B41: Grand Total | C41: 78 | E41: Primary_Category | F41: (All)
E43: Row Labels | F43: Average of Overall_Risk_Score | G43: Count of Seller_ID
E44: Apex Retail 055 | F44: 175 | G44: 1
E45: Apex Retail 095 | F45: 175 | G45: 1
E46: Blue Source 002 | F46: 175 | G46: 1
E47: Blue Source 042 | F47: 175 | G47: 1
E48: Bright Nest 008 | F48: 175 | G48: 1
E49: Ever Merchants 030 | F49: 175 | G49: 1
E50: Golden Hub 049 | F50: 200 | G50: 1
A51: Seller Count by Final Risk Level | E51: Golden Hub 069 | F51: 175 | G51: 1
A52: Analysis_Year | B52: 2021 | E52: Golden Hub 089 | F52: 175 | G52: 1
E53: Luna Stores 018 | F53: 175 | G53: 1
A54: Row Labels | B54: Count of Seller_ID | E54: Luna Stores 038 | F54: 175 | G54: 1
...
